2021-07-19 15:18:38,885:DEBUG:src.tools.logging - SUCCESS: Created user with parametrs : {'email': 'portes@gmail.com', 'name': 'string', 'nick_name': 'string', 'password': 'string'}
2021-07-19 15:19:06,471:ERROR:src.tools.logging - ERROR: bad arguments in request
Traceback (most recent call last):
  File "/usr/local/lib/python3.9/site-packages/sqlalchemy/engine/base.py", line 1771, in _execute_context
    self.dialect.do_execute(
  File "/usr/local/lib/python3.9/site-packages/sqlalchemy/engine/default.py", line 717, in do_execute
    cursor.execute(statement, parameters)
psycopg2.errors.UniqueViolation: duplicate key value violates unique constraint "users_nick_name_key"
DETAIL:  Key (nick_name)=(string) already exists.


The above exception was the direct cause of the following exception:

Traceback (most recent call last):
  File "/app/src/views/users_views.py", line 119, in post
    user = User.create(request_json)
  File "/app/src/models/users.py", line 52, in create
    user.save()
  File "/app/src/models/base.py", line 15, in save
    db.session.commit()
  File "<string>", line 2, in commit
  File "/usr/local/lib/python3.9/site-packages/sqlalchemy/orm/session.py", line 1428, in commit
    self._transaction.commit(_to_root=self.future)
  File "/usr/local/lib/python3.9/site-packages/sqlalchemy/orm/session.py", line 829, in commit
    self._prepare_impl()
  File "/usr/local/lib/python3.9/site-packages/sqlalchemy/orm/session.py", line 808, in _prepare_impl
    self.session.flush()
  File "/usr/local/lib/python3.9/site-packages/sqlalchemy/orm/session.py", line 3298, in flush
    self._flush(objects)
  File "/usr/local/lib/python3.9/site-packages/sqlalchemy/orm/session.py", line 3438, in _flush
    transaction.rollback(_capture_exception=True)
  File "/usr/local/lib/python3.9/site-packages/sqlalchemy/util/langhelpers.py", line 70, in __exit__
    compat.raise_(
  File "/usr/local/lib/python3.9/site-packages/sqlalchemy/util/compat.py", line 207, in raise_
    raise exception
  File "/usr/local/lib/python3.9/site-packages/sqlalchemy/orm/session.py", line 3398, in _flush
    flush_context.execute()
  File "/usr/local/lib/python3.9/site-packages/sqlalchemy/orm/unitofwork.py", line 456, in execute
    rec.execute(self)
  File "/usr/local/lib/python3.9/site-packages/sqlalchemy/orm/unitofwork.py", line 630, in execute
    util.preloaded.orm_persistence.save_obj(
  File "/usr/local/lib/python3.9/site-packages/sqlalchemy/orm/persistence.py", line 242, in save_obj
    _emit_insert_statements(
  File "/usr/local/lib/python3.9/site-packages/sqlalchemy/orm/persistence.py", line 1219, in _emit_insert_statements
    result = connection._execute_20(
  File "/usr/local/lib/python3.9/site-packages/sqlalchemy/engine/base.py", line 1583, in _execute_20
    return meth(self, args_10style, kwargs_10style, execution_options)
  File "/usr/local/lib/python3.9/site-packages/sqlalchemy/sql/elements.py", line 323, in _execute_on_connection
    return connection._execute_clauseelement(
  File "/usr/local/lib/python3.9/site-packages/sqlalchemy/engine/base.py", line 1452, in _execute_clauseelement
    ret = self._execute_context(
  File "/usr/local/lib/python3.9/site-packages/sqlalchemy/engine/base.py", line 1814, in _execute_context
    self._handle_dbapi_exception(
  File "/usr/local/lib/python3.9/site-packages/sqlalchemy/engine/base.py", line 1995, in _handle_dbapi_exception
    util.raise_(
  File "/usr/local/lib/python3.9/site-packages/sqlalchemy/util/compat.py", line 207, in raise_
    raise exception
  File "/usr/local/lib/python3.9/site-packages/sqlalchemy/engine/base.py", line 1771, in _execute_context
    self.dialect.do_execute(
  File "/usr/local/lib/python3.9/site-packages/sqlalchemy/engine/default.py", line 717, in do_execute
    cursor.execute(statement, parameters)
sqlalchemy.exc.IntegrityError: (psycopg2.errors.UniqueViolation) duplicate key value violates unique constraint "users_nick_name_key"
DETAIL:  Key (nick_name)=(string) already exists.

[SQL: INSERT INTO users (name, nick_name, email, pswhash, created, is_admin) VALUES (%(name)s, %(nick_name)s, %(email)s, %(pswhash)s, %(created)s, %(is_admin)s) RETURNING users.id]
[parameters: {'name': 'string', 'nick_name': 'string', 'email': 12, 'pswhash': 'sha256$9FrL3wsX$1ef9fc312c0c5789af6ca53fd96b640c6c5911f6a4425c894e6a03e83b6337d3', 'created': datetime.datetime(2021, 7, 19, 15, 19, 6, 410042), 'is_admin': False}]
(Background on this error at: https://sqlalche.me/e/14/gkpj)
2021-07-19 15:19:29,681:DEBUG:src.tools.logging - SUCCESS: Created user with parametrs : {'email': 12, 'name': 'string', 'nick_name': 'srtring', 'password': 'string'}
2021-07-19 15:32:53,604:ERROR:src.tools.logging - ERROR: bad arguments in request
Traceback (most recent call last):
  File "/app/src/views/users_views.py", line 119, in post
    user = User.create(request_json)
  File "/app/src/models/users.py", line 55, in create
    user = User(**data)
  File "<string>", line 4, in __init__
  File "/usr/local/lib/python3.9/site-packages/sqlalchemy/orm/state.py", line 480, in _initialize_instance
    manager.dispatch.init_failure(self, args, kwargs)
  File "/usr/local/lib/python3.9/site-packages/sqlalchemy/util/langhelpers.py", line 70, in __exit__
    compat.raise_(
  File "/usr/local/lib/python3.9/site-packages/sqlalchemy/util/compat.py", line 207, in raise_
    raise exception
  File "/usr/local/lib/python3.9/site-packages/sqlalchemy/orm/state.py", line 477, in _initialize_instance
    return manager.original_init(*mixed[1:], **kwargs)
  File "/app/src/models/users.py", line 46, in __init__
    self.email = email
  File "/usr/local/lib/python3.9/site-packages/sqlalchemy/orm/attributes.py", line 459, in __set__
    self.impl.set(
  File "/usr/local/lib/python3.9/site-packages/sqlalchemy/orm/attributes.py", line 1082, in set
    value = self.fire_replace_event(
  File "/usr/local/lib/python3.9/site-packages/sqlalchemy/orm/attributes.py", line 1090, in fire_replace_event
    value = fn(
  File "/usr/local/lib/python3.9/site-packages/sqlalchemy/orm/util.py", line 185, in set_
    return validator(state.obj(), key, value)
  File "/app/src/models/users.py", line 34, in validate_rating
    raise AssertionError("Bad field : 'email'")
AssertionError: Bad field : 'email'
2021-07-19 15:33:58,752:DEBUG:src.tools.logging - FAIL: Invalid email : string
2021-07-19 15:34:26,386:DEBUG:src.tools.logging - FAIL: Invalid password : string
2021-07-19 15:40:06,743:ERROR:src.tools.logging - ERROR: bad arguments in request
Traceback (most recent call last):
  File "/app/src/views/users_views.py", line 123, in post
    user = User.create(request_json)
  File "/app/src/models/users.py", line 55, in create
    user = User(**data)
  File "<string>", line 4, in __init__
  File "/usr/local/lib/python3.9/site-packages/sqlalchemy/orm/state.py", line 480, in _initialize_instance
    manager.dispatch.init_failure(self, args, kwargs)
  File "/usr/local/lib/python3.9/site-packages/sqlalchemy/util/langhelpers.py", line 70, in __exit__
    compat.raise_(
  File "/usr/local/lib/python3.9/site-packages/sqlalchemy/util/compat.py", line 207, in raise_
    raise exception
  File "/usr/local/lib/python3.9/site-packages/sqlalchemy/orm/state.py", line 477, in _initialize_instance
    return manager.original_init(*mixed[1:], **kwargs)
  File "/app/src/models/users.py", line 46, in __init__
    self.email = email
  File "/usr/local/lib/python3.9/site-packages/sqlalchemy/orm/attributes.py", line 459, in __set__
    self.impl.set(
  File "/usr/local/lib/python3.9/site-packages/sqlalchemy/orm/attributes.py", line 1082, in set
    value = self.fire_replace_event(
  File "/usr/local/lib/python3.9/site-packages/sqlalchemy/orm/attributes.py", line 1090, in fire_replace_event
    value = fn(
  File "/usr/local/lib/python3.9/site-packages/sqlalchemy/orm/util.py", line 185, in set_
    return validator(state.obj(), key, value)
  File "/app/src/models/users.py", line 34, in validate_rating
    raise AssertionError("Bad field : 'email'")
AssertionError: Bad field : 'email'
2021-07-19 15:41:17,506:DEBUG:src.tools.logging - SUCCESS: Created user with parametrs : {'email': '3@', 'is_admin': True, 'name': 'string', 'nick_name': 'string', 'password': '3'}
2021-07-19 15:41:45,775:INFO:src.tools.logging - SUCCESS: Login with nick_name : string
2021-07-19 15:42:00,190:INFO:src.tools.logging - SUCCESS. Deleted director with id : 500000
2021-07-19 15:44:03,000:INFO:src.tools.logging - SUCCESS. Deleted director with id : 500000
2021-07-19 15:44:07,290:INFO:src.tools.logging - SUCCESS. Deleted director with id : 500000
2021-07-19 15:44:10,682:INFO:src.tools.logging - SUCCESS. Deleted director with id : 500000
2021-07-19 15:50:27,786:INFO:src.tools.logging - SUCCESS. Deleted director with id : 4
2021-07-19 15:58:48,235:DEBUG:src.tools.logging - SUCCESS: Created film with parametrs : {'title': 'GHJ', 'release': '2017-3-18', 'description': 'afr оaid in all time', 'rating': 6.1, 'poster': 'ук75ded2hj2kdgfflrpl0ffhddльп'}
2021-07-19 15:59:38,071:DEBUG:src.tools.logging - SUCCESS: Created film with parametrs : {'title': 'GHJ', 'release': '2017-3-18', 'description': 'afr оaid in all time', 'rating': 6.1, 'poster': 'ук75ded2hj2kdgfflrpl0ffkhddльп'}
2021-07-19 16:00:02,099:DEBUG:src.tools.logging - SUCCESS: Created film with parametrs : {'title': 'GHJ', 'release': '2017-3-18', 'description': 'afr оaid in all time', 'rating': 6.1, 'poster': 'ук75ded2hj2kdgfflrpel0ffkhddльп'}
2021-07-19 19:28:31,061:INFO:src.tools.logging - SUCCESS. Deleted film with id : 36
